Workbook
Name Employee: Vlookup_Ans!$A$1:$G$16
Name Employee_2: Hlookup_ans!$A$1:$P$7
Name Employee2: Hlookup_ans!$A$1:$P$7

Sheet city_statew
D5: City | E5: Mumbai | F5: Udaipur | G5: Lucknow | H5: Surat | I5: Banaras | J5: Indore | K5: Pune | L5: Bhopal | M5: Jyotpur | N5: Ahmdabaad | O5: Gorakhpur
D6: State | E6: Maharashtra | F6: Rajasthan | G6: UP | H6: Gujrat | I6: UP | J6: MP | K6: Maharashtra | L6: MP | M6: Rajasthan | N6: Gujrat | O6: UP

Sheet Vlookup_Ans
A1: Name | B1: Age | C1: Salary | D1: TDS 3% | E1: Pass Out Year | F1: City | G1: State | K1: Find the following data of "Gitesh" using Vlookup.
A2: Ramesh | B2: 21 | C2: 25800 | D2: 774 | E2: 2016 | F2: Mumbai | G2: Maharashtra | K2: Name | L2: Gitesh
A3: Mahesh | B3: 43 | C3: 73000 | D3: 2190 | E3: 2014 | F3: Udaipur | G3: Rajasthan
A4: Suresh | B4: 32 | C4: 54999 | D4: 1649.97 | E4: 2016 | F4: Lucknow | G4: UP | K4: Age | L4: =_xlfn.XLOOKUP(L2,A2:A16,B2:B16,"not found") -> 34
A5: Jayesh | B5: 24 | C5: 45969 | D5: 1379.07 | E5: 2017 | F5: Surat | G5: Gujrat | K5: Salary | L5: =_xlfn.XLOOKUP(L2,A2:A16,C2:C16) -> 85000
A6: Jitesh | B6: 43 | C6: 65999 | D6: 1979.97 | E6: 2014 | F6: Banaras | G6: UP | K6: City | L6: Indore
A7: Gitesh | B7: 34 | C7: 85000 | D7: 2550 | E7: 2016 | F7: Indore | G7: MP | K7: Pass out Yr | L7: 2016
A8: kamlesh | B8: 32 | C8: 55869 | D8: 1676.07 | E8: 2016 | F8: Mumbai | G8: Maharashtra
A9: Hitesh | B9: 43 | C9: 58399 | D9: 1751.97 | E9: 2014 | F9: Pune | G9: Maharashtra
A10: Jay | B10: 23 | C10: 45858 | D10: 1375.74 | E10: 2019 | F10: Bhopal | G10: MP
A11: ajay | B11: 25 | C11: 46899 | D11: 1406.97 | E11: 2019 | F11: Indore | G11: MP
A12: Rajesh | B12: 28 | C12: 23500 | D12: 705 | E12: 2016 | F12: Jyotpur | G12: Rajasthan
A13: Sujay | B13: 32 | C13: 38000 | D13: 1140 | E13: 2014 | F13: Ahmdabaad | G13: Gujrat
A14: Sanjay | B14: 43 | C14: 28500 | D14: 855 | E14: 2019 | F14: Surat | G14: Gujrat
A15: Dhananjay | B15: 20 | C15: 48800 | D15: 1464 | E15: 2019 | F15: Gorakhpur | G15: UP
A16: Nirjay | B16: 37 | C16: 57300 | D16: 1719 | E16: 2014 | F16: Pune | G16: Maharashtra

Sheet Hlookup_ans
A1: Name | B1: Ramesh | C1: Mahesh | D1: Suresh | E1: Jayesh | F1: Jitesh | G1: Gitesh | H1: kamlesh | I1: Hitesh | J1: Jay | K1: ajay | L1: Rajesh | M1: Sujay | N1: Sanjay | O1: Dhananjay | P1: Nirjay
A2: Age | B2: 21 | C2: 43 | D2: 32 | E2: 24 | F2: 43 | G2: 34 | H2: 32 | I2: 43 | J2: 23 | K2: 25 | L2: 28 | M2: 32 | N2: 43 | O2: 20 | P2: 37
A3: Salary | B3: 25800 | C3: 73000 | D3: 54999 | E3: 45969 | F3: 65999 | G3: 85000 | H3: 55869 | I3: 58399 | J3: 45858 | K3: 46899 | L3: 23500 | M3: 38000 | N3: 28500 | O3: 48800 | P3: 57300
A4: TDS 3% | B4: =B3*3% -> 774 | C4: =C3*3% -> 2190 | D4: =D3*3% -> 1649.97 | E4: =E3*3% -> 1379.07 | F4: =F3*3% -> 1979.97 | G4: =G3*3% -> 2550 | H4: =H3*3% -> 1676.07 | I4: =I3*3% -> 1751.97 | ... P4: =P3*3% -> 1719
A5: Pass Out Year | B5: 2016 | C5: 2014 | D5: 2016 | E5: 2017 | F5: 2014 | G5: 2016 | H5: 2016 | I5: 2014 | J5: 2019 | K5: 2019 | L5: 2016 | M5: 2014 | N5: 2019 | O5: 2019 | P5: 2014
A6: City | B6: Mumbai | C6: Udaipur | D6: Lucknow | E6: Surat | F6: Banaras | G6: Indore | H6: Mumbai | I6: Pune | J6: Bhopal | K6: Indore | L6: Jyotpur | M6: Ahmdabaad | N6: Surat | O6: Gorakhpur | P6: Pune
A7: State | B7: =HLOOKUP(B6,city_statew!$E$5:$O$6,2,FALSE) -> Maharashtra | C7: =HLOOKUP(C6,city_statew!$E$5:$O$6,2,FALSE) -> Rajasthan | D7: =HLOOKUP(D6,city_statew!$E$5:$O$6,2,FALSE) -> UP | E7: =HLOOKUP(E6,city_statew!$E$5:$O$6,2,FALSE) -> Gujrat | F7: =HLOOKUP(F6,city_statew!$E$5:$O$6,2,FALSE) -> UP | G7: =HLOOKUP(G6,city_statew!$E$5:$O$6,2,FALSE) -> MP | H7: =HLOOKUP(H6,city_statew!$E$5:$O$6,2,FALSE) -> Maharashtra | I7: =HLOOKUP(I6,city_statew!$E$5:$O$6,2,FALSE) -> Maharashtra | ... P7: =HLOOKUP(P6,city_statew!$E$5:$O$6,2,FALSE) -> Maharashtra
A11: Name | C11: Age | D11: Salary | E11: City | F11: Pass out Yr
A12: Gitesh | C12: =HLOOKUP(A12,B1:P7,2,FALSE) -> 34 | D12: =HLOOKUP(A12,B1:P7,3,FALSE) -> 85000 | E12: =HLOOKUP(A12,B1:P7,6,FALSE) -> Indore | F12: =HLOOKUP(A12,B1:P7,5,FALSE) -> 2016

Sheet Sale_data
A1: Sales | B1: Commission % | C1: Rating
A2: 100000 | B2: =VLOOKUP(A2,$H$4:$K$8,3,TRUE) -> 0.02 | C2: =VLOOKUP(A2,$H$4:$K$8,4,TRUE) -> 1 | H2: Sales | J2: Commission % | K2: Rating
A3: 120000 | B3: =VLOOKUP(A3,$H$4:$K$8,3,TRUE) -> 0.04 | C3: =VLOOKUP(A3,$H$4:$K$8,4,TRUE) -> 2 | H3: Min Range | I3: Max Range
A4: 50000 | B4: =VLOOKUP(A4,$H$4:$K$8,3,TRUE) -> 0.02 | C4: =VLOOKUP(A4,$H$4:$K$8,4,TRUE) -> 1 | H4: 10000 | I4: 100000 | J4: 0.02 | K4: 1
A5: 90000 | B5: =VLOOKUP(A5,$H$4:$K$8,3,TRUE) -> 0.02 | C5: =VLOOKUP(A5,$H$4:$K$8,4,TRUE) -> 1 | H5: 100001 | I5: 200000 | J5: 0.04 | K5: 2
A6: 800000 | B6: =VLOOKUP(A6,$H$4:$K$8,3,TRUE) -> 0.1 | C6: =VLOOKUP(A6,$H$4:$K$8,4,TRUE) -> 5 | H6: 200001 | I6: 300000 | J6: 0.06 | K6: 3
A7: 200000 | B7: =VLOOKUP(A7,$H$4:$K$8,3,TRUE) -> 0.04 | C7: =VLOOKUP(A7,$H$4:$K$8,4,TRUE) -> 2 | H7: 300001 | I7: 400000 | J7: 0.08 | K7: 4
A8: 80000 | B8: =VLOOKUP(A8,$H$4:$K$8,3,TRUE) -> 0.02 | C8: =VLOOKUP(A8,$H$4:$K$8,4,TRUE) -> 1 | H8: 400001 | I8: Above | J8: 0.1 | K8: 5
A9: 90000 | B9: =VLOOKUP(A9,$H$4:$K$8,3,TRUE) -> 0.02 | C9: =VLOOKUP(A9,$H$4:$K$8,4,TRUE) -> 1
A10: 400000 | B10: =VLOOKUP(A10,$H$4:$K$8,3,TRUE) -> 0.08 | C10: =VLOOKUP(A10,$H$4:$K$8,4,TRUE) -> 4
A11: 300000 | B11: =VLOOKUP(A11,$H$4:$K$8,3,TRUE) -> 0.06 | C11: =VLOOKUP(A11,$H$4:$K$8,4,TRUE) -> 3
A12: 450000 | B12: =VLOOKUP(A12,$H$4:$K$8,3,TRUE) -> 0.1 | C12: =VLOOKUP(A12,$H$4:$K$8,4,TRUE) -> 5
A13: 300000 | B13: =VLOOKUP(A13,$H$4:$K$8,3,TRUE) -> 0.06 | C13: =VLOOKUP(A13,$H$4:$K$8,4,TRUE) -> 3
A14: 400000 | B14: =VLOOKUP(A14,$H$4:$K$8,3,TRUE) -> 0.08 | C14: =VLOOKUP(A14,$H$4:$K$8,4,TRUE) -> 4
A15: 500000 | B15: =VLOOKUP(A15,$H$4:$K$8,3,TRUE) -> 0.1 | C15: =VLOOKUP(A15,$H$4:$K$8,4,TRUE) -> 5
A16: 900000 | B16: =VLOOKUP(A16,$H$4:$K$8,3,TRUE) -> 0.1 | C16: =VLOOKUP(A16,$H$4:$K$8,4,TRUE) -> 5
A17: 400000 | B17: =VLOOKUP(A17,$H$4:$K$8,3,TRUE) -> 0.08 | C17: =VLOOKUP(A17,$H$4:$K$8,4,TRUE) -> 4
A21: Sales | B21: 100000 | C21: 120000 | D21: 50000 | E21: 90000 | F21: 800000 | G21: 200000 | H21: 80000 | I21: 90000 | J21: 400000 | K21: 300000 | L21: 450000 | M21: 300000 | N21: 400000 | O21: 500000 | P21: 900000 | Q21: 400000
A22: Commission % | B22: =HLOOKUP(B21,$D$26:$H$29,3,TRUE) -> 0.02 | C22: =HLOOKUP(C21,$D$26:$H$29,3,TRUE) -> 0.04 | D22: =HLOOKUP(D21,$D$26:$H$29,3,TRUE) -> 0.02 | E22: =HLOOKUP(E21,$D$26:$H$29,3,TRUE) -> 0.02 | F22: =HLOOKUP(F21,$D$26:$H$29,3,TRUE) -> 0.1 | G22: =HLOOKUP(G21,$D$26:$H$29,3,TRUE) -> 0.04 | H22: =HLOOKUP(H21,$D$26:$H$29,3,TRUE) -> 0.02 | I22: =HLOOKUP(I21,$D$26:$H$29,3,TRUE) -> 0.02 | ... Q22: =HLOOKUP(Q21,$D$26:$H$29,3,TRUE) -> 0.08
A23: Rating | B23: =HLOOKUP($B$21,$D$26:$H$29,4,TRUE) -> 1 | C23: =HLOOKUP(C21,$D$26:$H$29,4,TRUE) -> 2 | D23: =HLOOKUP(D21,$D$26:$H$29,4,TRUE) -> 1 | E23: =HLOOKUP(E21,$D$26:$H$29,4,TRUE) -> 1 | F23: =HLOOKUP(F21,$D$26:$H$29,4,TRUE) -> 5 | G23: =HLOOKUP(G21,$D$26:$H$29,4,TRUE) -> 2 | H23: =HLOOKUP(H21,$D$26:$H$29,4,TRUE) -> 1 | I23: =HLOOKUP(I21,$D$26:$H$29,4,TRUE) -> 1 | J23: =HLOOKUP(J21,$D$26:$H$29,4,TRUE) -> 4 | ... Q23: =HLOOKUP(Q21,$D$26:$H$29,4,TRUE) -> 4
B26: Sales | C26: Min Range | D26: 10000 | E26: 100001 | F26: 200001 | G26: 300001 | H26: 400001
C27: Max Range | D27: 100000 | E27: 200000 | F27: 300000 | G27: 400000 | H27: Above
B28: Commission % | D28: 0.02 | E28: 0.04 | F28: 0.06 | G28: 0.08 | H28: 0.1
B29: Rating | D29: 1 | E29: 2 | F29: 3 | G29: 4 | H29: 5

Sheet cons
A1: Total sales | B1: Q1 | C1: Q2 | D1: Q3 | E1: Q4 | H1: Min (3 years) | I1: Q1 | J1: Q2 | K1: Q3 | L1: Q4
A2: Laptop | B2: 150000 | C2: 200010 | D2: 400000 | E2: 770000 | H2: Laptop | I2: 50000 | J2: 100005 | K2: 200000 | L2: 320000
A3: Mobile | B3: 400000 | C3: 670000 | D3: 600000 | E3: 1100000 | H3: Mobile | I3: 200000 | J3: 320000 | K3: 200000 | L3: 400000
A4: Washing Machine | B4: 250000 | C4: 310002 | D4: 330000 | E4: 350006 | H4: Washing Machine | I4: 100000 | J4: 120001 | K4: 150000 | L4: 160003
A5: Smart Watches | B5: 40000 | C5: 120002 | D5: 70012 | E5: 130014 | H5: Smart Watches | I5: 20000 | J5: 50001 | K5: 30006 | L5: 60007
A6: Tabs | B6: 170000 | C6: 200002 | D6: 260004 | E6: 180006 | H6: Tabs | I6: 70000 | J6: 100001 | K6: 80002 | L6: 85003
A7: Smart Pens | B7: 40000 | C7: 59002 | D7: 70004 | E7: 76006 | H7: Smart Pens | I7: 20000 | J7: 24001 | K7: 25002 | L7: 33003
A10: Max(3 years) | B10: Q1 | C10: Q2 | D10: Q3 | E10: Q4 | H10: Average (3 years) | I10: Q1 | J10: Q2 | K10: Q3 | L10: Q4
A11: Laptop | B11: 200000 | C11: 200005 | D11: 400000 | E11: 450000 | H11: Laptop | I11: 116666.67 | J11: 133338.33 | K11: 266666.67 | L11: 396666.67
A12: Mobile | B12: 300000 | C12: 350000 | D12: 300000 | E12: 700000 | H12: Mobile | I12: 233333.33 | J12: 340000 | K12: 266666.67 | L12: 533333.33
A13: Washing Machine | B13: 150000 | C13: 160001 | D13: 180000 | E13: 180003 | H13: Washing Machine | I13: 123333.33 | J13: 143334.33 | K13: 160000 | L13: 170003
A14: Smart Watches | B14: 40000 | C14: 70001 | D14: 40006 | E14: 70007 | H14: Smart Watches | I14: 26666.667 | J14: 56667.667 | K14: 36672.667 | L14: 63340.333
A15: Tabs | B15: 100000 | C15: 100001 | D15: 180002 | E15: 95003 | H15: Tabs | I15: 86666.667 | J15: 100001 | K15: 113335.33 | L15: 88336.333
A16: Smart Pens | B16: 23000 | C16: 35001 | D16: 35002 | E16: 43003 | H16: Smart Pens | I16: 21000 | J16: 28001 | K16: 31668.667 | L16: 36336.333

Sheet cons2
A1: Sum | E1: Q1 | F1: Q2 | G1: Q3 | H1: Q4
E5: =[1]cansole1!$B$3 -> 200000 | F5: =[1]cansole1!$C$3 -> 200005 | G5: =[1]cansole1!$D$3 -> 400000 | H5: =[1]cansole1!$E$3 -> 420000
E9: =[1]cansole2!$B$3 -> 100000 | F9: =[1]cansole2!$C$3 -> 100005 | G9: =[1]cansole2!$D$3 -> 200000 | H9: =[1]cansole2!$E$3 -> 320000
E13: =[1]cansole3!$B$3 -> 50000 | F13: =[1]cansole3!$C$3 -> 100005 | G13: =[1]cansole3!$D$3 -> 200000 | H13: =[1]cansole3!$E$3 -> 450000
A17: Laptop | E17: =SUM(E5:E13) -> 350000 | F17: =SUM(F5:F13) -> 400015 | G17: =SUM(G5:G13) -> 800000 | H17: =SUM(H5:H13) -> 1190000
M18: Ass | N18: =[1]cansole1!$B$7 -> 90000 | O18: =[1]cansole1!$C$7 -> 100001 | P18: =[1]cansole1!$D$7 -> 80002 | Q18: =[1]cansole1!$E$7 -> 85003
M19: Ass | N19: =[1]cansole2!$B$7 -> 100000 | O19: =[1]cansole2!$C$7 -> 100001 | P19: =[1]cansole2!$D$7 -> 80002 | Q19: =[1]cansole2!$E$7 -> 95003
M20: Ass | N20: =[1]cansole3!$B$7 -> 70000 | O20: =[1]cansole3!$C$7 -> 100001 | P20: =[1]cansole3!$D$7 -> 180002 | Q20: =[1]cansole3!$E$7 -> 85003
E21: =[1]cansole1!$B$4 -> 300000 | F21: =[1]cansole1!$C$4 -> 350000 | G21: =[1]cansole1!$D$4 -> 200000 | H21: =[1]cansole1!$E$4 -> 500000 | L21: Tabs | N21: =MIN(N18:N20) -> 70000 | O21: =MIN(O18:O20) -> 100001 | P21: =MIN(P18:P20) -> 80002 | Q21: =MIN(Q18:Q20) -> 85003
M22: Ass | N22: =[1]cansole1!$B$8 -> 23000 | O22: =[1]cansole1!$C$8 -> 25001 | P22: =[1]cansole1!$D$8 -> 25002 | Q22: =[1]cansole1!$E$8 -> 33003
M23: Ass | N23: =[1]cansole2!$B$8 -> 20000 | O23: =[1]cansole2!$C$8 -> 35001 | P23: =[1]cansole2!$D$8 -> 35002 | Q23: =[1]cansole2!$E$8 -> 43003
M24: Ass | N24: =[1]cansole3!$B$8 -> 20000 | O24: =[1]cansole3!$C$8 -> 24001 | P24: =[1]cansole3!$D$8 -> 35002 | Q24: =[1]cansole3!$E$8 -> 33003
E25: =[1]cansole2!$B$4 -> 200000 | F25: =[1]cansole2!$C$4 -> 320000 | G25: =[1]cansole2!$D$4 -> 300000 | H25: =[1]cansole2!$E$4 -> 700000 | L25: Smart Pens | N25: =MIN(N22:N24) -> 20000 | O25: =MIN(O22:O24) -> 24001 | P25: =MIN(P22:P24) -> 25002 | Q25: =MIN(Q22:Q24) -> 33003
E26: =[1]cansole3!$B$4 -> 200000 | F26: =[1]cansole3!$C$4 -> 350000 | G26: =[1]cansole3!$D$4 -> 300000 | H26: =[1]cansole3!$E$4 -> 400000
A27: Mobile | E27: =SUM(E21:E26) -> 700000 | F27: =SUM(F21:F26) -> 1020000 | G27: =SUM(G21:G26) -> 800000 | H27: =SUM(H21:H26) -> 1600000
E28: =[1]cansole1!$B$5 -> 120000 | F28: =[1]cansole1!$C$5 -> 120001 | G28: =[1]cansole1!$D$5 -> 150000 | H28: =[1]cansole1!$E$5 -> 160003
E29: =[1]cansole2!$B$5 -> 100000 | F29: =[1]cansole2!$C$5 -> 150001 | G29: =[1]cansole2!$D$5 -> 150000 | H29: =[1]cansole2!$E$5 -> 180003
E30: =[1]cansole3!$B$5 -> 150000 | F30: =[1]cansole3!$C$5 -> 160001 | G30: =[1]cansole3!$D$5 -> 180000 | H30: =[1]cansole3!$E$5 -> 170003
A31: Washing Machine | E31: =SUM(E28:E30) -> 370000 | F31: =SUM(F28:F30) -> 430003 | G31: =SUM(G28:G30) -> 480000 | H31: =SUM(H28:H30) -> 510009
E32: =[1]cansole1!$B$6 -> 40000 | F32: =[1]cansole1!$C$6 -> 50001 | G32: =[1]cansole1!$D$6 -> 40006 | H32: =[1]cansole1!$E$6 -> 60007
E33: =[1]cansole2!$B$6 -> 20000 | F33: =[1]cansole2!$C$6 -> 50001 | G33: =[1]cansole2!$D$6 -> 30006 | H33: =[1]cansole2!$E$6 -> 70007
E34: =[1]cansole3!$B$6 -> 20000 | F34: =[1]cansole3!$C$6 -> 70001 | G34: =[1]cansole3!$D$6 -> 40006 | H34: =[1]cansole3!$E$6 -> 60007
A35: Smart Watches | E35: =SUM(E32:E34) -> 80000 | F35: =SUM(F32:F34) -> 170003 | G35: =SUM(G32:G34) -> 110018 | H35: =SUM(H32:H34) -> 190021
E36: =[1]cansole1!$B$7 -> 90000 | F36: =[1]cansole1!$C$7 -> 100001 | G36: =[1]cansole1!$D$7 -> 80002 | H36: =[1]cansole1!$E$7 -> 85003
E37: =[1]cansole2!$B$7 -> 100000 | F37: =[1]cansole2!$C$7 -> 100001 | G37: =[1]cansole2!$D$7 -> 80002 | H37: =[1]cansole2!$E$7 -> 95003
E38: =[1]cansole3!$B$7 -> 70000 | F38: =[1]cansole3!$C$7 -> 100001 | G38: =[1]cansole3!$D$7 -> 180002 | H38: =[1]cansole3!$E$7 -> 85003
A39: Tabs | E39: =SUM(E36:E38) -> 260000 | F39: =SUM(F36:F38) -> 300003 | G39: =SUM(G36:G38) -> 340006 | H39: =SUM(H36:H38) -> 265009
E40: =[1]cansole1!$B$8 -> 23000 | F40: =[1]cansole1!$C$8 -> 25001 | G40: =[1]cansole1!$D$8 -> 25002 | H40: =[1]cansole1!$E$8 -> 33003
E41: =[1]cansole2!$B$8 -> 20000 | F41: =[1]cansole2!$C$8 -> 35001 | G41: =[1]cansole2!$D$8 -> 35002 | H41: =[1]cansole2!$E$8 -> 43003
E42: =[1]cansole3!$B$8 -> 20000 | F42: =[1]cansole3!$C$8 -> 24001 | G42: =[1]cansole3!$D$8 -> 35002 | H42: =[1]cansole3!$E$8 -> 33003
A43: Smart Pens | E43: =SUM(E40:E42) -> 63000 | F43: =SUM(F40:F42) -> 84003 | G43: =SUM(G40:G42) -> 95006 | H43: =SUM(H40:H42) -> 109009
A47: Max | E47: Q1 | F47: Q2 | G47: Q3 | H47: Q4
B48: Ass | E48: =[1]cansole1!$B$3 -> 200000 | F48: =[1]cansole1!$C$3 -> 200005 | G48: =[1]cansole1!$D$3 -> 400000 | H48: =[1]cansole1!$E$3 -> 420000
B49: Ass | E49: =[1]cansole2!$B$3 -> 100000 | F49: =[1]cansole2!$C$3 -> 100005 | G49: =[1]cansole2!$D$3 -> 200000 | H49: =[1]cansole2!$E$3 -> 320000
B50: Ass | E50: =[1]cansole3!$B$3 -> 50000 | F50: =[1]cansole3!$C$3 -> 100005 | G50: =[1]cansole3!$D$3 -> 200000 | H50: =[1]cansole3!$E$3 -> 450000
A51: Laptop | E51: =MAX(E48:E50) -> 200000 | F51: =MAX(F48:F50) -> 200005 | G51: =MAX(G48:G50) -> 400000 | H51: =MAX(H48:H50) -> 450000
B52: Ass | E52: =[1]cansole1!$B$4 -> 300000 | F52: =[1]cansole1!$C$4 -> 350000 | G52: =[1]cansole1!$D$4 -> 200000 | H52: =[1]cansole1!$E$4 -> 500000
B53: Ass | E53: =[1]cansole2!$B$4 -> 200000 | F53: =[1]cansole2!$C$4 -> 320000 | G53: =[1]cansole2!$D$4 -> 300000 | H53: =[1]cansole2!$E$4 -> 700000
B54: Ass | E54: =[1]cansole3!$B$4 -> 200000 | F54: =[1]cansole3!$C$4 -> 350000 | G54: =[1]cansole3!$D$4 -> 300000 | H54: =[1]cansole3!$E$4 -> 400000
A55: Mobile | E55: =MAX(E52:E54) -> 300000 | F55: =MAX(F52:F54) -> 350000 | G55: =MAX(G52:G54) -> 300000 | H55: =MAX(H52:H54) -> 700000
...

Sheet Match
A1: What is the Column Number of Q1.
A2: =MATCH([1]Match!$B$2,[1]Match!$A$2:$E$2,0) -> 2
A4: What is the column number of Smart Watches.
A5: =MATCH([1]Match!$A$6,[1]Match!$A$6:$E$6,0) -> 1
A7: What is the column number of Q4.
A8: =MATCH([1]Match!$E$2,[1]Match!$E$2:$E$8,0) -> 1
A10: What is the row number of 43,003.
A11: =MATCH([1]Match!$E$8,[1]Match!$E$2:$E$8,0) -> 7
A13: What is the row number of Q4.
A14: =MATCH([1]Match!$E$2,[1]Match!$E$2:$E$8,0) -> 1
